<?xml version="1.0"?>
<robot xmlns:xacro="http://www.ros.org/wiki/xacro">

  <xacro:include filename="inertial_macros.xacro" />

  <!-- Colors -->
  <material name="white">
    <color rgba="1 1 1 1" />
  </material>
  <material name="orange">
    <color rgba="1 .3 0.1 1" />
  </material>
  <material name="blue">
    <color rgba="0 1 0 1" />
  </material>
  <material name="black">
    <color rgba="0 0 0 1" />
  </material>
  <material name="red">
    <color rgba="1 0 0 1" />
  </material>

  <!-- Links & Joints -->
  <link name="base_link">

  </link>

  <joint name="base_footprint_joint" type="fixed">
    <parent link="base_link"/>
    <child link="base_footprint"/>
    <origin xyz="0 0 0" rpy="0 0 0"/>  
  </joint>

  <link name="base_footprint">
  </link>

  <!-- Chassis link -->
  <joint name="chassis_joint" type="fixed">
    <parent link="base_link" />
    <child link="chassis_link" />
    <origin xyz="0.0 0.0 0.0" />
  </joint>

  <link name="chassis_link">
    <visual>
      <geometry>
        <box size="1.0 1.0 0.2" />
      </geometry>
      <origin xyz="0 0 0.1" />
      <material name="white"></material>
    </visual>
    <collision>
      <geometry>
        <box size="1.0 1.0 0.2" />
      </geometry>
      <origin xyz="0.0 0 0.1" />
      <material name="white"></material>
    </collision>
    <xacro:inertial_box mass="50.0" x="1.0" y="1.0" z="0.2">
      <origin xyz="0 0 0.1" rpy="0 0 0" />
    </xacro:inertial_box>
  </link>

  <gazebo reference="chassis_link">
    <material>Gazebo/Black</material>
  </gazebo>

  <!-- left wheel link -->

  <joint name="left_wheel_joint" type="continuous">
    <parent link="base_link" />
    <child link="left_wheel_link" />
    <origin xyz="0.0 0.45 0.0" rpy="-${pi/2} 0.0 0.0" />
    <axis xyz="0.0 0.0 1.0" />
    <joint_properties damping="1.0" friction="1.0" />
  </joint>

  <link name="left_wheel_link">
    <visual>
      <material name="blue"></material>
      <geometry>
        <cylinder radius="0.1" length="0.05" />
      </geometry>
    </visual>
    <collision>
    <surface>
   <contact>
    <ode>
     <kp>1.0</kp>
     <kd>0.01</kd>
     <max_vel>0.0</max_vel>
     <min_depth>0.001</min_depth>
    </ode>
   </contact>
   <friction>
    <ode>
     <mu>100.9</mu> 
     <mu2>100.9</mu2>
     <slip1> 0</slip1>
     <slip2>0</slip2>
    </ode>
   </friction>
  </surface>
      <material name="blue"></material>
      <geometry>
        <cylinder radius="0.1" length="0.05" />
      </geometry>
    </collision>
    <xacro:inertial_cylinder mass="0.1" length="0.1" radius="0.05">
      <origin xyz="0 0 0" rpy="0 0 0" />
    </xacro:inertial_cylinder>
  </link>

  <gazebo reference="left_wheel_link">
    <material>Gazebo/Blue</material>
  </gazebo>

  <!-- right wheel link -->

  <joint name="right_wheel_joint" type="continuous">
    <parent link="base_link" />
    <child link="right_wheel_link" />
    <origin xyz="0.0 -0.45 0.0" rpy="${pi/2} 0.0 0.0" />
    <axis xyz="0.0 0.0 -1.0" />
    <joint_properties damping="1.0" friction="1.0" />

  </joint>

  <link name="right_wheel_link">
    <visual>
      <material name="blue"></material>
      <geometry>
        <cylinder radius="0.1" length="0.05" />
      </geometry>
    </visual>
    <collision>
    <surface>
   <contact>
    <ode>
     <kp>1.0</kp>
     <kd>0.01</kd>
     <max_vel>0.0</max_vel>
     <min_depth>0.001</min_depth>
    </ode>
   </contact>
   <friction>
    <ode>
     <mu>100.9</mu> 
     <mu2>100.9</mu2>
     <slip1> 0</slip1>
     <slip2>0</slip2>
    </ode>
   </friction>
  </surface>
      <material name="blue"></material>
      <geometry>
        <cylinder radius="0.1" length="0.05" />
      </geometry>
    </collision>
    
    <xacro:inertial_cylinder mass="0.1" length="0.1" radius="0.05">
      <origin xyz="0 0 0" rpy="0 0 0" />
    </xacro:inertial_cylinder>
  </link>

  <gazebo reference="right_wheel_link">
    <material>Gazebo/Blue</material>
  </gazebo>

    <gazebo reference="right_wheel_link">
    
    <!-- <kp>1.0</kp>
    <kd>0.001</kd> -->
     <mu>100.9</mu> 
     <mu2>100.9</mu2>
    <!-- <fdir1>1 0 0</fdir1> -->
    <maxVel>0.0</maxVel>
    <minDepth>0.0001</minDepth>
  </gazebo>

    <gazebo reference="left_wheel_link">
    
    <!-- <kp>1.0</kp>
    <kd>0.001</kd> -->
     <mu>100.9</mu> 
     <mu2>100.9</mu2>
    <!-- <fdir1>1 0 0</fdir1> -->
    <maxVel>0.0</maxVel>
    <minDepth>0.0001</minDepth>
  </gazebo>

  <!-- caster wheels -->
  <!-- caster wheel first -->

  <joint name="caster_wheel_1_joint" type="fixed">
    <parent link="chassis_link" />
    <child link="caster_wheel_1_link" />
    <origin xyz="0.35 0.35 0.0001" />
  </joint>

  <link name="caster_wheel_1_link">
    <visual>
      <geometry>
        <sphere radius="0.1" />
      </geometry>
      <material name="black"></material>
    </visual>
    <collision>
      <geometry>
        <sphere radius="0.1" />
      </geometry>
      <material name="black"></material>
    </collision>
    <xacro:inertial_sphere mass="0.1" radius="0.1">
      <origin xyz="0 0 0" rpy="0 0 0" />
    </xacro:inertial_sphere>
  </link>

  <gazebo reference="caster_wheel_1_link">
    <material>Gazebo/Black</material>
    <!-- <mu1 value="0.001"/>
    <mu2 value="0.001"/> -->
  </gazebo>

  <!-- caster wheel second -->
  <joint name="caster_wheel_2_joint" type="fixed">
    <parent link="chassis_link" />
    <child link="caster_wheel_2_link" />
    <origin xyz="0.35 -0.35 0.0001" />
  </joint>

  <link name="caster_wheel_2_link">
    <visual>
      <geometry>
        <sphere radius="0.1" />
      </geometry>
      <material name="black"></material>
    </visual>
    <collision>
      <geometry>
        <sphere radius="0.1" />
      </geometry>
      <material name="black"></material>
    </collision>
    <xacro:inertial_sphere mass="0.1" radius="0.1">
      <origin xyz="0 0 0" rpy="0 0 0" />
    </xacro:inertial_sphere>
  </link>

  <gazebo reference="caster_wheel_2_link">
    <material>Gazebo/Black</material>
    <!-- <mu1 value="0.001"/>
    <mu2 value="0.001"/> -->
  </gazebo>

  <!-- caster wheel third -->
  <joint name="caster_wheel_3_joint" type="fixed">
    <parent link="chassis_link" />
    <child link="caster_wheel_3_link" />
    <origin xyz="-0.35 0.35 0.0001" />
  </joint>

  <link name="caster_wheel_3_link">
    <visual>
      <geometry>
        <sphere radius="0.1" />
      </geometry>
      <material name="black"></material>
    </visual>
    <collision>
      <geometry>
        <sphere radius="0.1" />
      </geometry>
      <material name="black"></material>
    </collision>
    <xacro:inertial_sphere mass="0.1" radius="0.1">
      <origin xyz="0 0 0" rpy="0 0 0" />
    </xacro:inertial_sphere>
  </link>

  <gazebo reference="caster_wheel_3_link">
    <material>Gazebo/Black</material>
    <!-- <mu1 value="0.001"/>
    <mu2 value="0.001"/> -->
  </gazebo>

  <!-- caster wheel fourth -->
  <joint name="caster_wheel_4_joint" type="fixed">
    <parent link="chassis_link" />
    <child link="caster_wheel_4_link" />
    <origin xyz="-0.35 -0.35 0.0001" />
  </joint>

  <link name="caster_wheel_4_link">
    <visual>
      <geometry>
        <sphere radius="0.1" />
      </geometry>
      <material name="black"></material>
    </visual>
    <collision>
      <geometry>
        <sphere radius="0.1" />
      </geometry>
      <material name="black"></material>
    </collision>
    <xacro:inertial_sphere mass="0.1" radius="0.1">
      <origin xyz="0 0 0" rpy="0 0 0" />
    </xacro:inertial_sphere>
  </link>

  <gazebo reference="caster_wheel_4_link">
    <material>Gazebo/Black</material>
    <!-- <mu1 value="0.001"/>
    <mu2 value="0.001"/> -->
  </gazebo>

</robot>